---
title: "에러처리 [모던 자바스크립트 Deep Dive 47장]"
date: "2022-07-09"
lastmod: "2022-07-09"
category: "JavaScript"
tags: ["try/catch", "에러처리"]
series: '"모던 자바스크립트 Deep Dive" 읽고 정리하기 📚'
description: "모던 자바스크립트 Deep Dive 47장 내용을 정리한 포스트입니다."
thumbNail: "https://github.com/BY-juun/Blog/assets/78716842/6b4065ee-7d44-4580-899f-58dafcb8b5a7"
---

<div align="right">
  [![Hits](https://hits.seeyoufarm.com/api/count/incr/badge.svg?url=https%3A%2F%2Fdevlog-juneby.vercel.app%2Fposts%2FJavaScript%2Fdeep-dive-js-47&count_bg=%233B82F6&title_bg=%23555555&icon=&icon_color=%23E7E7E7&title=views&edge_flat=false)](https://hits.seeyoufarm.com)
</div>

# 🌟에러 처리의 필요성

에러가 발생하지 않는 코드를 작성하는 것은 불가능하다. 따라서, 에러는 언제나 발생할 수 있다.

```jsx
console.log("[Start]");

foo(); // ReferenceError: foo is not defined
// 발생한 에러를 방치하면 프로그램은 강제 종료된다.

// 에러에 의해 프로그램이 강제 종료되어 아래 코드는 실행되지 않는다.
console.log("[End]");
```

`try ... catch` 문을 사용해, 에러에 적절하게 대응하면, 프로그램이 강제 종료되지 않고 계속해서 코드를 실행시킬 수 있다.

```jsx
console.log("[Start]");

try {
  foo();
} catch (error) {
  console.error("[에러 발생]", error);
  // [에러 발생] ReferenceError: foo is not defined
}

// 발생한 에러에 적절한 대응을 하면 프로그램이 강제 종료되지 않는다.
console.log("[End]");
```

<br />

# 🌟try ... catch ... finally 문

기본적으로 예외 처리를 구현하는 방법은 크게 두 가지가 있다. 예외적인 상황이 발생하면 반환하는 값(null 또는 -1)을 if 문이나 단축 평가 또는 옵셔널 체이닝 연산자를 통해 확인해서 처리하는 방법과, 에러 처리 코드를 미리 등록해 두고 에러가 발생하면, 에러 처리 코드로 점프하도록 하는 방법이 있다.

`try ... catch ... finally` 문은 두 번째 방법ㅂ이다.

`try ... catch ... finally` 문을 실행하면 먼저 `try` 코드 블록이 실행된다. 이때, `try` 코드 블록에 포함된 문 중에서 에러가 발생하면, 발생한 에러는 catch 문의 매게변수로 전달되고 catch 코드 블록이 실행된다.

`catch` 문의 매게변수는 `try` 코드 블록에 포함된 문 중에서 에러가 발생하면 생성되고, `catch` 코드 블록에서만 유효하다.

`finally` 코드 블록은 에러 발생과 상관없이 반드시 한번 실행된다.

```jsx
console.log("[Start]");

try {
  // 실행할 코드(에러가 발생할 가능성이 있는 코드)
  foo();
} catch (err) {
  // try 코드 블록에서 에러가 발생하면 이 코드 블록의 코드가 실행된다.
  // err에는 try 코드 블록에서 발생한 Error 객체가 전달된다.
  console.error(err); // ReferenceError: foo is not defined
} finally {
  // 에러 발생과 상관없이 반드시 한 번 실행된다.
  console.log("finally");
}

// try...catch...finally 문으로 에러를 처리하면 프로그램이 강제 종료되지 않는다.
console.log("[End]");
```

<br />

# 🌟Error 객체

`Error` 생성자 함수는 에러 객체를 생성한다. 에러를 상세히 설명하는 에러 메시지를 인수로 전달할 수 있다

```jsx
const error = new Error("invalid");
```

생성된 에러 객체는 `message` 프로퍼티와 `stack` 프로퍼티를 갖는다.

`message` 프로퍼티의 값은 `Error` 생성자 함수에 인수로 전달한 에러 메시지이고, `stack` 프로퍼티의 값은 에러를 발생시킨 콜 스택의 호출 정보를 나타낸다.

자바스크립트는 `Error` 생성자 함수를 포함해 7가지의 에러 객체를 생성할 수 있는 `Error` 생성자 함수를 제공한다. (SyntaxError, ReferenceError, TypeError, RangeError, URIError, EvalError)

<br />

# 🌟throw 문

에러를 발생시키려면 `try` 코드 블록에서 `throw` 문으로 에러 객체를 던져야 한다.

`throw` 문의 표현식은 어떤 값이라도 상관없지만, 일반적으로 에러 객체를 지정한다. 에러를 던지면 `catch` 문의 에러 변수가 생성되고 던져진 에러 객체가 할당된다.

```jsx
try {
  // 에러 객체를 던지면 catch 코드 블록이 실행되기 시작한다.
  throw new Error("something wrong");
} catch (error) {
  console.log(error);
}
```

<br />

# 🌟에러의 전파

에러는 호출자 방향 (즉, 콜 스택의 아래 방향) 으로 전파된다.

```jsx
const foo = () => {
  throw Error("foo에서 발생한 에러"); // ④
};

const bar = () => {
  foo(); // ③
};

const baz = () => {
  bar(); // ②
};

try {
  baz(); // ①
} catch (err) {
  console.error(err);
}
```

위 예제에서 `foo` 함수에서 발생한 에러는 콜 스택을 타고 내려가 전역 실행 컨텍스트에서 캐치된다.
